Workbook

Sheet Preventivo
B2: Preventivo realizzazione software gestionale
B3: L'altramusica
A7: DI: | B7: Footility.com di Mistretta Paolo | E7: PER: | F7: L'altramusica Cooperativa Sociale E.T.S.
A8: P.IVA: | B8: 10896740965 | E8: P.IVA: | F8: 6248450964
A9: C.C.I.A.A.: | B9: MI2564569 | E9: C.C.I.A.A.: | F9: -
A10: C.F: | B10: MSTPLA85S01M102S | E10: C.F: | F10: 6248450964
A11: INDIRIZZO: | B11: Via XXIV Maggio 87 | E11: INDIRIZZO: | F11: Corso Buones Aires
B12: 20099, Sesto San Giovanni, MI | F12: 20124, Milano
A13: CELL.: | B13: +39 338 91 70 501 | E13: CELL.: | F13: -
A14: E-MAIL: | B14: paolo.mistretta@footility.com | E14: E-MAIL: | F14: info@laltramusica.com
A15: Sito web: | B15: https://www.footility.com | E15: Sito web: | F15: https://www.laltramusica.com
A18: Data: | B18: =TODAY() -> 46014 | E18: Scadenza: | F18: =B18+15 -> 46029
A20: DESCRIZIONE GENERALE
A21: Data la complessità e la varietà di implicazioni presenti negli attuali dati, il preventivo è suddiviso in aree generiche. I dettagli di ciascuna area saranno realizzati e formalizzati progressivamente durante l'avanzamento del progetto. Questo approccio garantisce flessibilità e adattabilità, permettendo di rispondere in modo efficiente alle esigenze emergenti e di ottimizzare le risorse nel corso dello sviluppo del sistema gestionale.
A23: SOLUZIONE PROPOSTA
A24: FUNZIONALITA' | B24: DESCRIZIONE
A25: Gestione delle utenze | B25: Configurazione e gestione degli account utente, inclusa la registrazione degli utenti e l'assegnazione dei ruoli specifici a studenti, genitori, docenti e personale amministrativo.
A26: Controllo Accessi e Autorizzazioni | B26: Implementazione di sistemi di autenticazione e autorizzazione per garantire che l'accesso alle informazioni sia limitato in base al ruolo e alle competenze dell'utente. Questo include la gestione di password, l'autenticazione a più fattori e l'assegnazione di permessi specifici per le diverse aree del sistema.
A27: Anagrafica fornitori e clienti
A28: Generazione attestati di frequenza
A29: Comunicazione Mail / SMS
A30: Gestione aule
A31: Lezioi libere
A32: Pacchetto lezioni
A33: Supplenti / Supplenza | B33: occhio alla gestione pagamenti in base a insegnante o supplente
A34: Prospetto previsionale lezioni
A35: Gestione Studenti | B35: Gestione completa dei dati anagrafici degli studenti dal primo contatto fino alla loro conversione in clienti, inclusa la gestione delle informazioni didattiche e personali. Include i dettagli relativi agli studenti e ai genitori/tutori, le note amministrative specifiche e la gestione della privacy dei dati.
A36: Gestione Genitori/Tutore | B36: Conservazione delle informazioni dei genitori o tutori per contatti e transazioni finanziarie; essenziale per le comunicazioni riguardo pagamenti e iscrizioni. Incluso nel dettaglio sono i dati di contatto e la comunicazione, oltre alla gestione della privacy.
A37: Gestione Fatturazione, Pagamenti e Recupero Crediti | B37: Tracciamento delle fatture, rate di pagamento, note di credito e recupero crediti. Include dettagli specifici relativi alle fatture, rata di pagamento, e il totale annuale dei pagamenti.
A38: Iscrizione e Corsi | B38: Registrazione dettagliata delle iscrizioni e dei corsi, incluse informazioni su date di inizio e conclusione dei corsi, descrizione dettagliata dei corsi compresa di tipologia e descrizione. Gestisce anche la schedulazione delle classi basata su vari parametri e monitoraggio dei livelli ABRSM.
A39: Gestione Accessori e Strumenti Musicali | B39: Gestione del noleggio e acquisto di strumenti musicali e altri accessori, con dettagli finanziari come cauzioni e rate di noleggio. Include informazioni dettagliate sul noleggio. Inclusione della gestione dei libri didattici, con operazioni di tracciamento, acquisto, e distribuzione dei libri necessari per i corsi e le attività extra.
A40: Attività Extra (Orchestra/Coro) | B40: Organizzazione e gestione delle attività extracurriculari come orchestre e cori, con la gestione di eventi e le relative iscrizioni. Include dettagli specifici su partecipazione e costi relativi a orchestre e cori.
A41: Gestione Esami | B41: Amministrazione degli esami, inclusi i costi di iscrizione e la pianificazione, in linea con i livelli ABRSM qualora applicabile. Gestisce anche dettagli specifici sugli esami.
A42: Comunicazione e Privacy | B42: Gestione delle comunicazioni e della privacy, inclusi i dettagli su come i clienti siano venuti a conoscenza dell'istituto e la gestione della privacy delle foto. Implementa un sistema di comunicazione integrato per invio di email, WhatsApp o altri sistemi (se applicabili)
A43: Amministrazione e Contratti | B43: Gestione dei contratti, dal rilascio alla firma, incluso il monitoraggio delle scadenze contrattuali e la gestione dei documenti legali come la privacy. Include la gestione documentale completa dei contratti, i dettagli sullo stato del contratto e termini. (da verificare implementazione con sistemi esterni)
A44: Gestione Docenti | B44: Gestione delle informazioni anagrafiche dei docenti, inclusi contratti, assegnazioni a corsi, e accesso ai profili didattici per la gestione delle attività di insegnamento. Soci non soci --> posso stabilire di dare la supervisione di un determinato progetto con un forfet stabilito. Aggiungere voci forfettarie aggiuntive
A45: Pianificazione Annuale e Reportistica | B45: Preparazione per le iscrizioni annuali, programmazione dei calendari e riepiloghi contabili fino al termine dell'anno scolastico. Include la visualizzazione di statistiche con grafici o informaizoni testuali
A46: Sicurezza e Integrità dei Dati | B46: Implementazione di misure di sicurezza per la protezione dei dati personali e sensibili secondo le normative vigenti (es. GDPR). Sistema di backup e ripristino dati per garantire la continuità operativa e la sicurezza delle informazioni.
A48: roardmap | B48: dati
A49: 1 - primo contatto
...

Sheet Implementazioni
B1: Programma Gestionale | R1: CONTO IMPLEMENTAZIONI | AI1: TEMPI | AY1: Ore lavoro calssiche | AZ1: 8 | BC1: COSTI | BS1: Tariffa minuti | BT1: 0.83
AY2: Ore lavoro per cliente | AZ2: 2 | BS2: Tariffa ora | BT2: 50
AY3: Minuti lavorazione | AZ3: 5
AI4: =5*DevUnits!B20 -> 25 | AJ4: =5*DevUnits!C20 -> 10 | AK4: =5*DevUnits!D20 -> 25 | AL4: =5*DevUnits!E20 -> 35 | AM4: =5*DevUnits!F20 -> 35 | AN4: =5*DevUnits!G20 -> 35 | AO4: =5*DevUnits!H20 -> 5 | AP4: =5*DevUnits!I20 -> 35 | ... AX4: =5*DevUnits!Q20 -> 25 | AY4: Minuti totali | AZ4: Ore Totali | BA4: Giorni (8 ore) | BB4: Consgena (2 ore) | BC4: =$BT$1*AI4 -> 20.75 | BD4: =$BT$1*AJ4 -> 8.3 | BE4: =$BT$1*AK4 -> 20.75 | BF4: =$BT$1*AL4 -> 29.05 | BG4: =$BT$1*AM4 -> 29.05 | BH4: =$BT$1*AN4 -> 29.05 | BI4: =$BT$1*AO4 -> 4.15 | BJ4: =$BT$1*AP4 -> 29.05 | ... BR4: =$BT$1*AX4 -> 20.75 | BS4: totale unitario
A5: Scenario | B5: enity | C5: field | D5: index | E5: create | F5: store | G5: show | H5: edit | I5: update | J5: destory | K5: soft-delete | L5: filter | M5: sorting | N5: validation | O5: oto | P5: otm | Q5: mtm | R5: enity | S5: field | T5: index | U5: create | V5: store | W5: show | X5: edit | Y5: update | Z5: destory | AA5: soft-delete | AB5: filter | AC5: sorting | AD5: validation | AE5: oto | AF5: otm | AG5: mtm | AH5: Totale | AI5: enity | AJ5: field | AK5: index | AL5: create | AM5: store | AN5: show | AO5: edit | AP5: update | AQ5: destory | AR5: soft-delete | AS5: filter | AT5: sorting | AU5: validation | AV5: oto | AW5: otm | AX5: mtm | BC5: enity | BD5: field | BE5: index | BF5: create | BG5: store | BH5: show | BI5: edit | BJ5: update | BK5: destory | BL5: soft-delete | BM5: filter | BN5: sorting | BO5: validation | BP5: oto | BQ5: otm | BR5: mtm
D6: =$B6 | E6: =$B6 | F6: =$B6 | G6: =$B6 | H6: =$B6 | I6: =$B6 | K6: =B6 | M6: =C6 | R6: =IFERROR(__xludf.DUMMYFUNCTION("(COUNTA(SPLIT(B6,"","",TRUE)) - NOT(LEN(B6)))"),0.0) -> 0 | S6: =IFERROR(__xludf.DUMMYFUNCTION("(COUNTA(SPLIT(C6,"","",TRUE)) - NOT(LEN(C6)))"),0.0) -> 0 | T6: =IFERROR(__xludf.DUMMYFUNCTION("(COUNTA(SPLIT(D6,"","",TRUE)) - NOT(LEN(D6)))"),0.0) -> 0 | U6: =IFERROR(__xludf.DUMMYFUNCTION("(COUNTA(SPLIT(E6,"","",TRUE)) - NOT(LEN(E6)))"),0.0) -> 0 | V6: =IFERROR(__xludf.DUMMYFUNCTION("(COUNTA(SPLIT(F6,"","",TRUE)) - NOT(LEN(F6)))"),0.0) -> 0 | W6: =IFERROR(__xludf.DUMMYFUNCTION("(COUNTA(SPLIT(G6,"","",TRUE)) - NOT(LEN(G6)))"),0.0) -> 0 | X6: =IFERROR(__xludf.DUMMYFUNCTION("(COUNTA(SPLIT(H6,"","",TRUE)) - NOT(LEN(H6)))"),0.0) -> 0 | Y6: =IFERROR(__xludf.DUMMYFUNCTION("(COUNTA(SPLIT(I6,"","",TRUE)) - NOT(LEN(I6)))"),0.0) -> 0 | Z6: =IFERROR(__xludf.DUMMYFUNCTION("(COUNTA(SPLIT(J6,"","",TRUE)) - NOT(LEN(J6)))"),0.0) -> 0 | AA6: =IFERROR(__xludf.DUMMYFUNCTION("(COUNTA(SPLIT(K6,"","",TRUE)) - NOT(LEN(K6)))"),0.0) -> 0 | AB6: =IFERROR(__xludf.DUMMYFUNCTION("(COUNTA(SPLIT(L6,"","",TRUE)) - NOT(LEN(L6)))"),0.0) -> 0 | AC6: =IFERROR(__xludf.DUMMYFUNCTION("(COUNTA(SPLIT(M6,"","",TRUE)) - NOT(LEN(M6)))"),0.0) -> 0 | AD6: =IFERROR(__xludf.DUMMYFUNCTION("(COUNTA(SPLIT(N6,"","",TRUE)) - NOT(LEN(N6)))"),0.0) -> 0 | AE6: =IFERROR(__xludf.DUMMYFUNCTION("(COUNTA(SPLIT(O6,"","",TRUE)) - NOT(LEN(O6)))"),0.0) -> 0 | AF6: =IFERROR(__xludf.DUMMYFUNCTION("(COUNTA(SPLIT(P6,"","",TRUE)) - NOT(LEN(P6)))"),0.0) -> 0 | AG6: =IFERROR(__xludf.DUMMYFUNCTION("(COUNTA(SPLIT(Q6,"","",TRUE)) - NOT(LEN(Q6)))"),0.0) -> 0 | AH6: =SUM(R6:AG6) -> 0 | AI6: =R6*AI$4 -> 0 | AJ6: =S6*AJ$4 -> 0 | AK6: =T6*AK$4 -> 0 | AL6: =U6*AL$4 -> 0 | AM6: =V6*AM$4 -> 0 | AN6: =W6*AN$4 -> 0 | AO6: =X6*AO$4 -> 0 | AP6: =Y6*AP$4 -> 0 | ... AX6: =AG6*AX$4 -> 0 | AY6: =SUM(AI6:AX6) -> 0 | AZ6: =AY6/60 -> 0 | BA6: =AZ6/$AZ$1 -> 0 | BB6: =AZ6/2 -> 0 | BC6: =R6*BC$4 -> 0 | BD6: =S6*BD$4 -> 0 | BE6: =T6*BE$4 -> 0 | BF6: =U6*BF$4 -> 0 | BG6: =V6*BG$4 -> 0 | BH6: =W6*BH$4 -> 0 | BI6: =X6*BI$4 -> 0 | BJ6: =Y6*BJ$4 -> 0 | ... BR6: =AG6*BR$4 -> 0 | BS6: =sum(BC6:BR6) -> 0
B7: documenti | C7: upload | D7: =$B7 -> documenti | E7: =$B7 -> documenti | F7: =$B7 -> documenti | H7: =$B7 -> documenti | I7: =$B7 -> documenti | K7: =B7 -> documenti | L7: =C7 -> upload | M7: =C7 -> upload | N7: =C7 -> upload | R7: =IFERROR(__xludf.DUMMYFUNCTION("(COUNTA(SPLIT(B7,"","",TRUE)) - NOT(LEN(B7)))"),1.0) -> 1 | S7: =IFERROR(__xludf.DUMMYFUNCTION("(COUNTA(SPLIT(C7,"","",TRUE)) - NOT(LEN(C7)))"),1.0) -> 1 | T7: =IFERROR(__xludf.DUMMYFUNCTION("(COUNTA(SPLIT(D7,"","",TRUE)) - NOT(LEN(D7)))"),1.0) -> 1 | U7: =IFERROR(__xludf.DUMMYFUNCTION("(COUNTA(SPLIT(E7,"","",TRUE)) - NOT(LEN(E7)))"),1.0) -> 1 | V7: =IFERROR(__xludf.DUMMYFUNCTION("(COUNTA(SPLIT(F7,"","",TRUE)) - NOT(LEN(F7)))"),1.0) -> 1 | W7: =IFERROR(__xludf.DUMMYFUNCTION("(COUNTA(SPLIT(G7,"","",TRUE)) - NOT(LEN(G7)))"),0.0) -> 0 | X7: =IFERROR(__xludf.DUMMYFUNCTION("(COUNTA(SPLIT(H7,"","",TRUE)) - NOT(LEN(H7)))"),1.0) -> 1 | Y7: =IFERROR(__xludf.DUMMYFUNCTION("(COUNTA(SPLIT(I7,"","",TRUE)) - NOT(LEN(I7)))"),1.0) -> 1 | Z7: =IFERROR(__xludf.DUMMYFUNCTION("(COUNTA(SPLIT(J7,"","",TRUE)) - NOT(LEN(J7)))"),0.0) -> 0 | AA7: =IFERROR(__xludf.DUMMYFUNCTION("(COUNTA(SPLIT(K7,"","",TRUE)) - NOT(LEN(K7)))"),1.0) -> 1 | AB7: =IFERROR(__xludf.DUMMYFUNCTION("(COUNTA(SPLIT(L7,"","",TRUE)) - NOT(LEN(L7)))"),1.0) -> 1 | AC7: =IFERROR(__xludf.DUMMYFUNCTION("(COUNTA(SPLIT(M7,"","",TRUE)) - NOT(LEN(M7)))"),1.0) -> 1 | AD7: =IFERROR(__xludf.DUMMYFUNCTION("(COUNTA(SPLIT(N7,"","",TRUE)) - NOT(LEN(N7)))"),1.0) -> 1 | AE7: =IFERROR(__xludf.DUMMYFUNCTION("(COUNTA(SPLIT(O7,"","",TRUE)) - NOT(LEN(O7)))"),0.0) -> 0 | AF7: =IFERROR(__xludf.DUMMYFUNCTION("(COUNTA(SPLIT(P7,"","",TRUE)) - NOT(LEN(P7)))"),0.0) -> 0 | AG7: =IFERROR(__xludf.DUMMYFUNCTION("(COUNTA(SPLIT(Q7,"","",TRUE)) - NOT(LEN(Q7)))"),0.0) -> 0 | AH7: =SUM(R7:AG7) -> 11 | AI7: =R7*AI$4 -> 25 | AJ7: =S7*AJ$4 -> 10 | AK7: =T7*AK$4 -> 25 | AL7: =U7*AL$4 -> 35 | AM7: =V7*AM$4 -> 35 | AN7: =W7*AN$4 -> 0 | AO7: =X7*AO$4 -> 5 | AP7: =Y7*AP$4 -> 35 | ... AX7: =AG7*AX$4 -> 0 | AY7: =SUM(AI7:AX7) -> 240 | AZ7: =AY7/60 -> 4 | BA7: =AZ7/$AZ$1 -> 0.5 | BB7: =AZ7/2 -> 2 | BC7: =R7*BC$4 -> 20.75 | BD7: =S7*BD$4 -> 8.3 | BE7: =T7*BE$4 -> 20.75 | BF7: =U7*BF$4 -> 29.05 | BG7: =V7*BG$4 -> 29.05 | BH7: =W7*BH$4 -> 0 | BI7: =X7*BI$4 -> 4.15 | BJ7: =Y7*BJ$4 -> 29.05 | ... BR7: =AG7*BR$4 -> 0 | BS7: =sum(BC7:BR7) -> 199.2
D8: =$B8 | E8: =$B8 | F8: =$B8 | G8: =$B8 | H8: =$B8 | I8: =$B8 | K8: =B8 | L8: =C8 | M8: =C8 | N8: =C8 | R8: =IFERROR(__xludf.DUMMYFUNCTION("(COUNTA(SPLIT(B8,"","",TRUE)) - NOT(LEN(B8)))"),0.0) -> 0 | S8: =IFERROR(__xludf.DUMMYFUNCTION("(COUNTA(SPLIT(C8,"","",TRUE)) - NOT(LEN(C8)))"),0.0) -> 0 | T8: =IFERROR(__xludf.DUMMYFUNCTION("(COUNTA(SPLIT(D8,"","",TRUE)) - NOT(LEN(D8)))"),0.0) -> 0 | U8: =IFERROR(__xludf.DUMMYFUNCTION("(COUNTA(SPLIT(E8,"","",TRUE)) - NOT(LEN(E8)))"),0.0) -> 0 | V8: =IFERROR(__xludf.DUMMYFUNCTION("(COUNTA(SPLIT(F8,"","",TRUE)) - NOT(LEN(F8)))"),0.0) -> 0 | W8: =IFERROR(__xludf.DUMMYFUNCTION("(COUNTA(SPLIT(G8,"","",TRUE)) - NOT(LEN(G8)))"),0.0) -> 0 | X8: =IFERROR(__xludf.DUMMYFUNCTION("(COUNTA(SPLIT(H8,"","",TRUE)) - NOT(LEN(H8)))"),0.0) -> 0 | Y8: =IFERROR(__xludf.DUMMYFUNCTION("(COUNTA(SPLIT(I8,"","",TRUE)) - NOT(LEN(I8)))"),0.0) -> 0 | Z8: =IFERROR(__xludf.DUMMYFUNCTION("(COUNTA(SPLIT(J8,"","",TRUE)) - NOT(LEN(J8)))"),0.0) -> 0 | AA8: =IFERROR(__xludf.DUMMYFUNCTION("(COUNTA(SPLIT(K8,"","",TRUE)) - NOT(LEN(K8)))"),0.0) -> 0 | AB8: =IFERROR(__xludf.DUMMYFUNCTION("(COUNTA(SPLIT(L8,"","",TRUE)) - NOT(LEN(L8)))"),0.0) -> 0 | AC8: =IFERROR(__xludf.DUMMYFUNCTION("(COUNTA(SPLIT(M8,"","",TRUE)) - NOT(LEN(M8)))"),0.0) -> 0 | AD8: =IFERROR(__xludf.DUMMYFUNCTION("(COUNTA(SPLIT(N8,"","",TRUE)) - NOT(LEN(N8)))"),0.0) -> 0 | AE8: =IFERROR(__xludf.DUMMYFUNCTION("(COUNTA(SPLIT(O8,"","",TRUE)) - NOT(LEN(O8)))"),0.0) -> 0 | AF8: =IFERROR(__xludf.DUMMYFUNCTION("(COUNTA(SPLIT(P8,"","",TRUE)) - NOT(LEN(P8)))"),0.0) -> 0 | AG8: =IFERROR(__xludf.DUMMYFUNCTION("(COUNTA(SPLIT(Q8,"","",TRUE)) - NOT(LEN(Q8)))"),0.0) -> 0 | AH8: =SUM(R8:AG8) -> 0 | AI8: =R8*AI$4 -> 0 | AJ8: =S8*AJ$4 -> 0 | AK8: =T8*AK$4 -> 0 | AL8: =U8*AL$4 -> 0 | AM8: =V8*AM$4 -> 0 | AN8: =W8*AN$4 -> 0 | AO8: =X8*AO$4 -> 0 | AP8: =Y8*AP$4 -> 0 | ... AX8: =AG8*AX$4 -> 0 | AY8: =SUM(AI8:AX8) -> 0 | AZ8: =AY8/60 -> 0 | BA8: =AZ8/$AZ$1 -> 0 | BB8: =AZ8/2 -> 0 | BC8: =R8*BC$4 -> 0 | BD8: =S8*BD$4 -> 0 | BE8: =T8*BE$4 -> 0 | BF8: =U8*BF$4 -> 0 | BG8: =V8*BG$4 -> 0 | BH8: =W8*BH$4 -> 0 | BI8: =X8*BI$4 -> 0 | BJ8: =Y8*BJ$4 -> 0 | ... BR8: =AG8*BR$4 -> 0 | BS8: =sum(BC8:BR8) -> 0
D9: =$B9 | L9: =C9 | M9: =C9 | R9: =IFERROR(__xludf.DUMMYFUNCTION("(COUNTA(SPLIT(B9,"","",TRUE)) - NOT(LEN(B9)))"),0.0) -> 0 | S9: =IFERROR(__xludf.DUMMYFUNCTION("(COUNTA(SPLIT(C9,"","",TRUE)) - NOT(LEN(C9)))"),0.0) -> 0 | T9: =IFERROR(__xludf.DUMMYFUNCTION("(COUNTA(SPLIT(D9,"","",TRUE)) - NOT(LEN(D9)))"),0.0) -> 0 | U9: =IFERROR(__xludf.DUMMYFUNCTION("(COUNTA(SPLIT(E9,"","",TRUE)) - NOT(LEN(E9)))"),0.0) -> 0 | V9: =IFERROR(__xludf.DUMMYFUNCTION("(COUNTA(SPLIT(F9,"","",TRUE)) - NOT(LEN(F9)))"),0.0) -> 0 | W9: =IFERROR(__xludf.DUMMYFUNCTION("(COUNTA(SPLIT(G9,"","",TRUE)) - NOT(LEN(G9)))"),0.0) -> 0 | X9: =IFERROR(__xludf.DUMMYFUNCTION("(COUNTA(SPLIT(H9,"","",TRUE)) - NOT(LEN(H9)))"),0.0) -> 0 | Y9: =IFERROR(__xludf.DUMMYFUNCTION("(COUNTA(SPLIT(I9,"","",TRUE)) - NOT(LEN(I9)))"),0.0) -> 0 | Z9: =IFERROR(__xludf.DUMMYFUNCTION("(COUNTA(SPLIT(J9,"","",TRUE)) - NOT(LEN(J9)))"),0.0) -> 0 | AA9: =IFERROR(__xludf.DUMMYFUNCTION("(COUNTA(SPLIT(K9,"","",TRUE)) - NOT(LEN(K9)))"),0.0) -> 0 | AB9: =IFERROR(__xludf.DUMMYFUNCTION("(COUNTA(SPLIT(L9,"","",TRUE)) - NOT(LEN(L9)))"),0.0) -> 0 | AC9: =IFERROR(__xludf.DUMMYFUNCTION("(COUNTA(SPLIT(M9,"","",TRUE)) - NOT(LEN(M9)))"),0.0) -> 0 | AD9: =IFERROR(__xludf.DUMMYFUNCTION("(COUNTA(SPLIT(N9,"","",TRUE)) - NOT(LEN(N9)))"),0.0) -> 0 | AE9: =IFERROR(__xludf.DUMMYFUNCTION("(COUNTA(SPLIT(O9,"","",TRUE)) - NOT(LEN(O9)))"),0.0) -> 0 | AF9: =IFERROR(__xludf.DUMMYFUNCTION("(COUNTA(SPLIT(P9,"","",TRUE)) - NOT(LEN(P9)))"),0.0) -> 0 | AG9: =IFERROR(__xludf.DUMMYFUNCTION("(COUNTA(SPLIT(Q9,"","",TRUE)) - NOT(LEN(Q9)))"),0.0) -> 0 | AH9: =SUM(R9:AG9) -> 0 | AI9: =R9*AI$4 -> 0 | AJ9: =S9*AJ$4 -> 0 | AK9: =T9*AK$4 -> 0 | AL9: =U9*AL$4 -> 0 | AM9: =V9*AM$4 -> 0 | AN9: =W9*AN$4 -> 0 | AO9: =X9*AO$4 -> 0 | AP9: =Y9*AP$4 -> 0 | ... AX9: =AG9*AX$4 -> 0 | AY9: =SUM(AI9:AX9) -> 0 | AZ9: =AY9/60 -> 0 | BA9: =AZ9/$AZ$1 -> 0 | BB9: =AZ9/2 -> 0 | BC9: =R9*BC$4 -> 0 | BD9: =S9*BD$4 -> 0 | BE9: =T9*BE$4 -> 0 | BF9: =U9*BF$4 -> 0 | BG9: =V9*BG$4 -> 0 | BH9: =W9*BH$4 -> 0 | BI9: =X9*BI$4 -> 0 | BJ9: =Y9*BJ$4 -> 0 | ... BR9: =AG9*BR$4 -> 0
D10: =$B10 | E10: =$B10 | F10: =$B10 | G10: =$B10 | H10: =$B10 | I10: =$B10 | K10: =B10 | L10: =C10 | M10: =C10 | N10: =C10 | R10: =IFERROR(__xludf.DUMMYFUNCTION("(COUNTA(SPLIT(B10,"","",TRUE)) - NOT(LEN(B10)))"),0.0) -> 0 | S10: =IFERROR(__xludf.DUMMYFUNCTION("(COUNTA(SPLIT(C10,"","",TRUE)) - NOT(LEN(C10)))"),0.0) -> 0 | T10: =IFERROR(__xludf.DUMMYFUNCTION("(COUNTA(SPLIT(D10,"","",TRUE)) - NOT(LEN(D10)))"),0.0) -> 0 | U10: =IFERROR(__xludf.DUMMYFUNCTION("(COUNTA(SPLIT(E10,"","",TRUE)) - NOT(LEN(E10)))"),0.0) -> 0 | V10: =IFERROR(__xludf.DUMMYFUNCTION("(COUNTA(SPLIT(F10,"","",TRUE)) - NOT(LEN(F10)))"),0.0) -> 0 | W10: =IFERROR(__xludf.DUMMYFUNCTION("(COUNTA(SPLIT(G10,"","",TRUE)) - NOT(LEN(G10)))"),0.0) -> 0 | X10: =IFERROR(__xludf.DUMMYFUNCTION("(COUNTA(SPLIT(H10,"","",TRUE)) - NOT(LEN(H10)))"),0.0) -> 0 | Y10: =IFERROR(__xludf.DUMMYFUNCTION("(COUNTA(SPLIT(I10,"","",TRUE)) - NOT(LEN(I10)))"),0.0) -> 0 | Z10: =IFERROR(__xludf.DUMMYFUNCTION("(COUNTA(SPLIT(J10,"","",TRUE)) - NOT(LEN(J10)))"),0.0) -> 0 | AA10: =IFERROR(__xludf.DUMMYFUNCTION("(COUNTA(SPLIT(K10,"","",TRUE)) - NOT(LEN(K10)))"),0.0) -> 0 | AB10: =IFERROR(__xludf.DUMMYFUNCTION("(COUNTA(SPLIT(L10,"","",TRUE)) - NOT(LEN(L10)))"),0.0) -> 0 | AC10: =IFERROR(__xludf.DUMMYFUNCTION("(COUNTA(SPLIT(M10,"","",TRUE)) - NOT(LEN(M10)))"),0.0) -> 0 | AD10: =IFERROR(__xludf.DUMMYFUNCTION("(COUNTA(SPLIT(N10,"","",TRUE)) - NOT(LEN(N10)))"),0.0) -> 0 | AE10: =IFERROR(__xludf.DUMMYFUNCTION("(COUNTA(SPLIT(O10,"","",TRUE)) - NOT(LEN(O10)))"),0.0) -> 0 | AF10: =IFERROR(__xludf.DUMMYFUNCTION("(COUNTA(SPLIT(P10,"","",TRUE)) - NOT(LEN(P10)))"),0.0) -> 0 | AG10: =IFERROR(__xludf.DUMMYFUNCTION("(COUNTA(SPLIT(Q10,"","",TRUE)) - NOT(LEN(Q10)))"),0.0) -> 0 | AH10: =SUM(R10:AG10) -> 0 | AI10: =R10*AI$4 -> 0 | AJ10: =S10*AJ$4 -> 0 | AK10: =T10*AK$4 -> 0 | AL10: =U10*AL$4 -> 0 | AM10: =V10*AM$4 -> 0 | AN10: =W10*AN$4 -> 0 | AO10: =X10*AO$4 -> 0 | AP10: =Y10*AP$4 -> 0 | ... AX10: =AG10*AX$4 -> 0 | AY10: =SUM(AI10:AX10) -> 0 | AZ10: =AY10/60 -> 0 | BA10: =AZ10/$AZ$1 -> 0 | BB10: =AZ10/2 -> 0 | BC10: =R10*BC$4 -> 0 | BD10: =S10*BD$4 -> 0 | BE10: =T10*BE$4 -> 0 | BF10: =U10*BF$4 -> 0 | BG10: =V10*BG$4 -> 0 | BH10: =W10*BH$4 -> 0 | BI10: =X10*BI$4 -> 0 | BJ10: =Y10*BJ$4 -> 0 | ... BR10: =AG10*BR$4 -> 0
D11: =$B11 | E11: =$B11 | F11: =$B11 | G11: =$B11 | H11: =$B11 | I11: =$B11 | K11: =B11 | L11: =C11 | M11: =C11 | N11: =C11 | R11: =IFERROR(__xludf.DUMMYFUNCTION("(COUNTA(SPLIT(B11,"","",TRUE)) - NOT(LEN(B11)))"),0.0) -> 0 | S11: =IFERROR(__xludf.DUMMYFUNCTION("(COUNTA(SPLIT(C11,"","",TRUE)) - NOT(LEN(C11)))"),0.0) -> 0 | T11: =IFERROR(__xludf.DUMMYFUNCTION("(COUNTA(SPLIT(D11,"","",TRUE)) - NOT(LEN(D11)))"),0.0) -> 0 | U11: =IFERROR(__xludf.DUMMYFUNCTION("(COUNTA(SPLIT(E11,"","",TRUE)) - NOT(LEN(E11)))"),0.0) -> 0 | V11: =IFERROR(__xludf.DUMMYFUNCTION("(COUNTA(SPLIT(F11,"","",TRUE)) - NOT(LEN(F11)))"),0.0) -> 0 | W11: =IFERROR(__xludf.DUMMYFUNCTION("(COUNTA(SPLIT(G11,"","",TRUE)) - NOT(LEN(G11)))"),0.0) -> 0 | X11: =IFERROR(__xludf.DUMMYFUNCTION("(COUNTA(SPLIT(H11,"","",TRUE)) - NOT(LEN(H11)))"),0.0) -> 0 | Y11: =IFERROR(__xludf.DUMMYFUNCTION("(COUNTA(SPLIT(I11,"","",TRUE)) - NOT(LEN(I11)))"),0.0) -> 0 | Z11: =IFERROR(__xludf.DUMMYFUNCTION("(COUNTA(SPLIT(J11,"","",TRUE)) - NOT(LEN(J11)))"),0.0) -> 0 | AA11: =IFERROR(__xludf.DUMMYFUNCTION("(COUNTA(SPLIT(K11,"","",TRUE)) - NOT(LEN(K11)))"),0.0) -> 0 | AB11: =IFERROR(__xludf.DUMMYFUNCTION("(COUNTA(SPLIT(L11,"","",TRUE)) - NOT(LEN(L11)))"),0.0) -> 0 | AC11: =IFERROR(__xludf.DUMMYFUNCTION("(COUNTA(SPLIT(M11,"","",TRUE)) - NOT(LEN(M11)))"),0.0) -> 0 | AD11: =IFERROR(__xludf.DUMMYFUNCTION("(COUNTA(SPLIT(N11,"","",TRUE)) - NOT(LEN(N11)))"),0.0) -> 0 | AE11: =IFERROR(__xludf.DUMMYFUNCTION("(COUNTA(SPLIT(O11,"","",TRUE)) - NOT(LEN(O11)))"),0.0) -> 0 | AF11: =IFERROR(__xludf.DUMMYFUNCTION("(COUNTA(SPLIT(P11,"","",TRUE)) - NOT(LEN(P11)))"),0.0) -> 0 | AG11: =IFERROR(__xludf.DUMMYFUNCTION("(COUNTA(SPLIT(Q11,"","",TRUE)) - NOT(LEN(Q11)))"),0.0) -> 0 | AH11: =SUM(R11:AG11) -> 0 | AI11: =R11*AI$4 -> 0 | AJ11: =S11*AJ$4 -> 0 | AK11: =T11*AK$4 -> 0 | AL11: =U11*AL$4 -> 0 | AM11: =V11*AM$4 -> 0 | AN11: =W11*AN$4 -> 0 | AO11: =X11*AO$4 -> 0 | AP11: =Y11*AP$4 -> 0 | ... AX11: =AG11*AX$4 -> 0 | AY11: =SUM(AI11:AX11) -> 0 | AZ11: =AY11/60 -> 0 | BA11: =AZ11/$AZ$1 -> 0 | BB11: =AZ11/2 -> 0 | BC11: =R11*BC$4 -> 0 | BD11: =S11*BD$4 -> 0 | BE11: =T11*BE$4 -> 0 | BF11: =U11*BF$4 -> 0 | BG11: =V11*BG$4 -> 0 | BH11: =W11*BH$4 -> 0 | BI11: =X11*BI$4 -> 0 | BJ11: =Y11*BJ$4 -> 0 | ... BR11: =AG11*BR$4 -> 0 | BS11: =sum(BC11:BR11) -> 0
D12: =$B12 | E12: =$B12 | F12: =$B12 | G12: =$B12 | H12: =$B12 | I12: =$B12 | K12: =B12 | L12: =C12 | M12: =C12 | N12: =C12 | R12: =IFERROR(__xludf.DUMMYFUNCTION("(COUNTA(SPLIT(B12,"","",TRUE)) - NOT(LEN(B12)))"),0.0) -> 0 | S12: =IFERROR(__xludf.DUMMYFUNCTION("(COUNTA(SPLIT(C12,"","",TRUE)) - NOT(LEN(C12)))"),0.0) -> 0 | T12: =IFERROR(__xludf.DUMMYFUNCTION("(COUNTA(SPLIT(D12,"","",TRUE)) - NOT(LEN(D12)))"),0.0) -> 0 | U12: =IFERROR(__xludf.DUMMYFUNCTION("(COUNTA(SPLIT(E12,"","",TRUE)) - NOT(LEN(E12)))"),0.0) -> 0 | V12: =IFERROR(__xludf.DUMMYFUNCTION("(COUNTA(SPLIT(F12,"","",TRUE)) - NOT(LEN(F12)))"),0.0) -> 0 | W12: =IFERROR(__xludf.DUMMYFUNCTION("(COUNTA(SPLIT(G12,"","",TRUE)) - NOT(LEN(G12)))"),0.0) -> 0 | X12: =IFERROR(__xludf.DUMMYFUNCTION("(COUNTA(SPLIT(H12,"","",TRUE)) - NOT(LEN(H12)))"),0.0) -> 0 | Y12: =IFERROR(__xludf.DUMMYFUNCTION("(COUNTA(SPLIT(I12,"","",TRUE)) - NOT(LEN(I12)))"),0.0) -> 0 | Z12: =IFERROR(__xludf.DUMMYFUNCTION("(COUNTA(SPLIT(J12,"","",TRUE)) - NOT(LEN(J12)))"),0.0) -> 0 | AA12: =IFERROR(__xludf.DUMMYFUNCTION("(COUNTA(SPLIT(K12,"","",TRUE)) - NOT(LEN(K12)))"),0.0) -> 0 | AB12: =IFERROR(__xludf.DUMMYFUNCTION("(COUNTA(SPLIT(L12,"","",TRUE)) - NOT(LEN(L12)))"),0.0) -> 0 | AC12: =IFERROR(__xludf.DUMMYFUNCTION("(COUNTA(SPLIT(M12,"","",TRUE)) - NOT(LEN(M12)))"),0.0) -> 0 | AD12: =IFERROR(__xludf.DUMMYFUNCTION("(COUNTA(SPLIT(N12,"","",TRUE)) - NOT(LEN(N12)))"),0.0) -> 0 | AE12: =IFERROR(__xludf.DUMMYFUNCTION("(COUNTA(SPLIT(O12,"","",TRUE)) - NOT(LEN(O12)))"),0.0) -> 0 | AF12: =IFERROR(__xludf.DUMMYFUNCTION("(COUNTA(SPLIT(P12,"","",TRUE)) - NOT(LEN(P12)))"),0.0) -> 0 | AG12: =IFERROR(__xludf.DUMMYFUNCTION("(COUNTA(SPLIT(Q12,"","",TRUE)) - NOT(LEN(Q12)))"),0.0) -> 0 | AH12: =SUM(R12:AG12) -> 0 | AI12: =R12*AI$4 -> 0 | AJ12: =S12*AJ$4 -> 0 | AK12: =T12*AK$4 -> 0 | AL12: =U12*AL$4 -> 0 | AM12: =V12*AM$4 -> 0 | AN12: =W12*AN$4 -> 0 | AO12: =X12*AO$4 -> 0 | AP12: =Y12*AP$4 -> 0 | ... AX12: =AG12*AX$4 -> 0 | AY12: =SUM(AI12:AX12) -> 0 | AZ12: =AY12/60 -> 0 | BA12: =AZ12/$AZ$1 -> 0 | BB12: =AZ12/2 -> 0 | BC12: =R12*BC$4 -> 0 | BD12: =S12*BD$4 -> 0 | BE12: =T12*BE$4 -> 0 | BF12: =U12*BF$4 -> 0 | BG12: =V12*BG$4 -> 0 | BH12: =W12*BH$4 -> 0 | BI12: =X12*BI$4 -> 0 | BJ12: =Y12*BJ$4 -> 0 | ... BR12: =AG12*BR$4 -> 0 | BS12: =sum(BC12:BR12) -> 0
D13: =$B13 | E13: =$B13 | F13: =$B13 | G13: =$B13 | H13: =$B13 | I13: =$B13 | K13: =B13 | L13: =C13 | M13: =C13 | N13: =C13 | R13: =IFERROR(__xludf.DUMMYFUNCTION("(COUNTA(SPLIT(B13,"","",TRUE)) - NOT(LEN(B13)))"),0.0) -> 0 | S13: =IFERROR(__xludf.DUMMYFUNCTION("(COUNTA(SPLIT(C13,"","",TRUE)) - NOT(LEN(C13)))"),0.0) -> 0 | T13: =IFERROR(__xludf.DUMMYFUNCTION("(COUNTA(SPLIT(D13,"","",TRUE)) - NOT(LEN(D13)))"),0.0) -> 0 | U13: =IFERROR(__xludf.DUMMYFUNCTION("(COUNTA(SPLIT(E13,"","",TRUE)) - NOT(LEN(E13)))"),0.0) -> 0 | V13: =IFERROR(__xludf.DUMMYFUNCTION("(COUNTA(SPLIT(F13,"","",TRUE)) - NOT(LEN(F13)))"),0.0) -> 0 | W13: =IFERROR(__xludf.DUMMYFUNCTION("(COUNTA(SPLIT(G13,"","",TRUE)) - NOT(LEN(G13)))"),0.0) -> 0 | X13: =IFERROR(__xludf.DUMMYFUNCTION("(COUNTA(SPLIT(H13,"","",TRUE)) - NOT(LEN(H13)))"),0.0) -> 0 | Y13: =IFERROR(__xludf.DUMMYFUNCTION("(COUNTA(SPLIT(I13,"","",TRUE)) - NOT(LEN(I13)))"),0.0) -> 0 | Z13: =IFERROR(__xludf.DUMMYFUNCTION("(COUNTA(SPLIT(J13,"","",TRUE)) - NOT(LEN(J13)))"),0.0) -> 0 | AA13: =IFERROR(__xludf.DUMMYFUNCTION("(COUNTA(SPLIT(K13,"","",TRUE)) - NOT(LEN(K13)))"),0.0) -> 0 | AB13: =IFERROR(__xludf.DUMMYFUNCTION("(COUNTA(SPLIT(L13,"","",TRUE)) - NOT(LEN(L13)))"),0.0) -> 0 | AC13: =IFERROR(__xludf.DUMMYFUNCTION("(COUNTA(SPLIT(M13,"","",TRUE)) - NOT(LEN(M13)))"),0.0) -> 0 | AD13: =IFERROR(__xludf.DUMMYFUNCTION("(COUNTA(SPLIT(N13,"","",TRUE)) - NOT(LEN(N13)))"),0.0) -> 0 | AE13: =IFERROR(__xludf.DUMMYFUNCTION("(COUNTA(SPLIT(O13,"","",TRUE)) - NOT(LEN(O13)))"),0.0) -> 0 | AF13: =IFERROR(__xludf.DUMMYFUNCTION("(COUNTA(SPLIT(P13,"","",TRUE)) - NOT(LEN(P13)))"),0.0) -> 0 | AG13: =IFERROR(__xludf.DUMMYFUNCTION("(COUNTA(SPLIT(Q13,"","",TRUE)) - NOT(LEN(Q13)))"),0.0) -> 0 | AH13: =SUM(R13:AG13) -> 0 | AI13: =R13*AI$4 -> 0 | AJ13: =S13*AJ$4 -> 0 | AK13: =T13*AK$4 -> 0 | AL13: =U13*AL$4 -> 0 | AM13: =V13*AM$4 -> 0 | AN13: =W13*AN$4 -> 0 | AO13: =X13*AO$4 -> 0 | AP13: =Y13*AP$4 -> 0 | ... AX13: =AG13*AX$4 -> 0 | AY13: =SUM(AI13:AX13) -> 0 | AZ13: =AY13/60 -> 0 | BA13: =AZ13/$AZ$1 -> 0 | BB13: =AZ13/2 -> 0 | BC13: =R13*BC$4 -> 0 | BD13: =S13*BD$4 -> 0 | BE13: =T13*BE$4 -> 0 | BF13: =U13*BF$4 -> 0 | BG13: =V13*BG$4 -> 0 | BH13: =W13*BH$4 -> 0 | BI13: =X13*BI$4 -> 0 | BJ13: =Y13*BJ$4 -> 0 | ... BR13: =AG13*BR$4 -> 0 | BS13: =sum(BC13:BR13) -> 0
D14: =$B14 | E14: =$B14 | F14: =$B14 | G14: =$B14 | H14: =$B14 | I14: =$B14 | K14: =B14 | L14: =C14 | M14: =C14 | N14: =C14 | R14: =IFERROR(__xludf.DUMMYFUNCTION("(COUNTA(SPLIT(B14,"","",TRUE)) - NOT(LEN(B14)))"),0.0) -> 0 | S14: =IFERROR(__xludf.DUMMYFUNCTION("(COUNTA(SPLIT(C14,"","",TRUE)) - NOT(LEN(C14)))"),0.0) -> 0 | T14: =IFERROR(__xludf.DUMMYFUNCTION("(COUNTA(SPLIT(D14,"","",TRUE)) - NOT(LEN(D14)))"),0.0) -> 0 | U14: =IFERROR(__xludf.DUMMYFUNCTION("(COUNTA(SPLIT(E14,"","",TRUE)) - NOT(LEN(E14)))"),0.0) -> 0 | V14: =IFERROR(__xludf.DUMMYFUNCTION("(COUNTA(SPLIT(F14,"","",TRUE)) - NOT(LEN(F14)))"),0.0) -> 0 | W14: =IFERROR(__xludf.DUMMYFUNCTION("(COUNTA(SPLIT(G14,"","",TRUE)) - NOT(LEN(G14)))"),0.0) -> 0 | X14: =IFERROR(__xludf.DUMMYFUNCTION("(COUNTA(SPLIT(H14,"","",TRUE)) - NOT(LEN(H14)))"),0.0) -> 0 | Y14: =IFERROR(__xludf.DUMMYFUNCTION("(COUNTA(SPLIT(I14,"","",TRUE)) - NOT(LEN(I14)))"),0.0) -> 0 | Z14: =IFERROR(__xludf.DUMMYFUNCTION("(COUNTA(SPLIT(J14,"","",TRUE)) - NOT(LEN(J14)))"),0.0) -> 0 | AA14: =IFERROR(__xludf.DUMMYFUNCTION("(COUNTA(SPLIT(K14,"","",TRUE)) - NOT(LEN(K14)))"),0.0) -> 0 | AB14: =IFERROR(__xludf.DUMMYFUNCTION("(COUNTA(SPLIT(L14,"","",TRUE)) - NOT(LEN(L14)))"),0.0) -> 0 | AC14: =IFERROR(__xludf.DUMMYFUNCTION("(COUNTA(SPLIT(M14,"","",TRUE)) - NOT(LEN(M14)))"),0.0) -> 0 | AD14: =IFERROR(__xludf.DUMMYFUNCTION("(COUNTA(SPLIT(N14,"","",TRUE)) - NOT(LEN(N14)))"),0.0) -> 0 | AE14: =IFERROR(__xludf.DUMMYFUNCTION("(COUNTA(SPLIT(O14,"","",TRUE)) - NOT(LEN(O14)))"),0.0) -> 0 | AF14: =IFERROR(__xludf.DUMMYFUNCTION("(COUNTA(SPLIT(P14,"","",TRUE)) - NOT(LEN(P14)))"),0.0) -> 0 | AG14: =IFERROR(__xludf.DUMMYFUNCTION("(COUNTA(SPLIT(Q14,"","",TRUE)) - NOT(LEN(Q14)))"),0.0) -> 0 | AH14: =SUM(R14:AG14) -> 0 | AI14: =R14*AI$4 -> 0 | AJ14: =S14*AJ$4 -> 0 | AK14: =T14*AK$4 -> 0 | AL14: =U14*AL$4 -> 0 | AM14: =V14*AM$4 -> 0 | AN14: =W14*AN$4 -> 0 | AO14: =X14*AO$4 -> 0 | AP14: =Y14*AP$4 -> 0 | ... AX14: =AG14*AX$4 -> 0 | AY14: =SUM(AI14:AX14) -> 0 | AZ14: =AY14/60 -> 0 | BA14: =AZ14/$AZ$1 -> 0 | BB14: =AZ14/2 -> 0 | BC14: =R14*BC$4 -> 0 | BD14: =S14*BD$4 -> 0 | BE14: =T14*BE$4 -> 0 | BF14: =U14*BF$4 -> 0 | BG14: =V14*BG$4 -> 0 | BH14: =W14*BH$4 -> 0 | BI14: =X14*BI$4 -> 0 | BJ14: =Y14*BJ$4 -> 0 | ... BR14: =AG14*BR$4 -> 0 | BS14: =sum(BC14:BR14) -> 0
D15: =$B15 | E15: =$B15 | F15: =$B15 | G15: =$B15 | H15: =$B15 | I15: =$B15 | K15: =B15 | L15: =C15 | M15: =C15 | N15: =C15 | R15: =IFERROR(__xludf.DUMMYFUNCTION("(COUNTA(SPLIT(B15,"","",TRUE)) - NOT(LEN(B15)))"),0.0) -> 0 | S15: =IFERROR(__xludf.DUMMYFUNCTION("(COUNTA(SPLIT(C15,"","",TRUE)) - NOT(LEN(C15)))"),0.0) -> 0 | T15: =IFERROR(__xludf.DUMMYFUNCTION("(COUNTA(SPLIT(D15,"","",TRUE)) - NOT(LEN(D15)))"),0.0) -> 0 | U15: =IFERROR(__xludf.DUMMYFUNCTION("(COUNTA(SPLIT(E15,"","",TRUE)) - NOT(LEN(E15)))"),0.0) -> 0 | V15: =IFERROR(__xludf.DUMMYFUNCTION("(COUNTA(SPLIT(F15,"","",TRUE)) - NOT(LEN(F15)))"),0.0) -> 0 | W15: =IFERROR(__xludf.DUMMYFUNCTION("(COUNTA(SPLIT(G15,"","",TRUE)) - NOT(LEN(G15)))"),0.0) -> 0 | X15: =IFERROR(__xludf.DUMMYFUNCTION("(COUNTA(SPLIT(H15,"","",TRUE)) - NOT(LEN(H15)))"),0.0) -> 0 | Y15: =IFERROR(__xludf.DUMMYFUNCTION("(COUNTA(SPLIT(I15,"","",TRUE)) - NOT(LEN(I15)))"),0.0) -> 0 | Z15: =IFERROR(__xludf.DUMMYFUNCTION("(COUNTA(SPLIT(J15,"","",TRUE)) - NOT(LEN(J15)))"),0.0) -> 0 | AA15: =IFERROR(__xludf.DUMMYFUNCTION("(COUNTA(SPLIT(K15,"","",TRUE)) - NOT(LEN(K15)))"),0.0) -> 0 | AB15: =IFERROR(__xludf.DUMMYFUNCTION("(COUNTA(SPLIT(L15,"","",TRUE)) - NOT(LEN(L15)))"),0.0) -> 0 | AC15: =IFERROR(__xludf.DUMMYFUNCTION("(COUNTA(SPLIT(M15,"","",TRUE)) - NOT(LEN(M15)))"),0.0) -> 0 | AD15: =IFERROR(__xludf.DUMMYFUNCTION("(COUNTA(SPLIT(N15,"","",TRUE)) - NOT(LEN(N15)))"),0.0) -> 0 | AE15: =IFERROR(__xludf.DUMMYFUNCTION("(COUNTA(SPLIT(O15,"","",TRUE)) - NOT(LEN(O15)))"),0.0) -> 0 | AF15: =IFERROR(__xludf.DUMMYFUNCTION("(COUNTA(SPLIT(P15,"","",TRUE)) - NOT(LEN(P15)))"),0.0) -> 0 | AG15: =IFERROR(__xludf.DUMMYFUNCTION("(COUNTA(SPLIT(Q15,"","",TRUE)) - NOT(LEN(Q15)))"),0.0) -> 0 | AH15: =SUM(R15:AG15) -> 0 | AI15: =R15*AI$4 -> 0 | AJ15: =S15*AJ$4 -> 0 | AK15: =T15*AK$4 -> 0 | AL15: =U15*AL$4 -> 0 | AM15: =V15*AM$4 -> 0 | AN15: =W15*AN$4 -> 0 | AO15: =X15*AO$4 -> 0 | AP15: =Y15*AP$4 -> 0 | ... AX15: =AG15*AX$4 -> 0 | AY15: =SUM(AI15:AX15) -> 0 | AZ15: =AY15/60 -> 0 | BA15: =AZ15/$AZ$1 -> 0 | BB15: =AZ15/2 -> 0 | BC15: =R15*BC$4 -> 0 | BD15: =S15*BD$4 -> 0 | BE15: =T15*BE$4 -> 0 | BF15: =U15*BF$4 -> 0 | BG15: =V15*BG$4 -> 0 | BH15: =W15*BH$4 -> 0 | BI15: =X15*BI$4 -> 0 | BJ15: =Y15*BJ$4 -> 0 | ... BR15: =AG15*BR$4 -> 0 | BS15: =sum(BC15:BR15) -> 0
D16: =$B16 | E16: =$B16 | F16: =$B16 | G16: =$B16 | H16: =$B16 | I16: =$B16 | K16: =B16 | L16: =C16 | M16: =C16 | N16: =C16 | R16: =IFERROR(__xludf.DUMMYFUNCTION("(COUNTA(SPLIT(B16,"","",TRUE)) - NOT(LEN(B16)))"),0.0) -> 0 | S16: =IFERROR(__xludf.DUMMYFUNCTION("(COUNTA(SPLIT(C16,"","",TRUE)) - NOT(LEN(C16)))"),0.0) -> 0 | T16: =IFERROR(__xludf.DUMMYFUNCTION("(COUNTA(SPLIT(D16,"","",TRUE)) - NOT(LEN(D16)))"),0.0) -> 0 | U16: =IFERROR(__xludf.DUMMYFUNCTION("(COUNTA(SPLIT(E16,"","",TRUE)) - NOT(LEN(E16)))"),0.0) -> 0 | V16: =IFERROR(__xludf.DUMMYFUNCTION("(COUNTA(SPLIT(F16,"","",TRUE)) - NOT(LEN(F16)))"),0.0) -> 0 | W16: =IFERROR(__xludf.DUMMYFUNCTION("(COUNTA(SPLIT(G16,"","",TRUE)) - NOT(LEN(G16)))"),0.0) -> 0 | X16: =IFERROR(__xludf.DUMMYFUNCTION("(COUNTA(SPLIT(H16,"","",TRUE)) - NOT(LEN(H16)))"),0.0) -> 0 | Y16: =IFERROR(__xludf.DUMMYFUNCTION("(COUNTA(SPLIT(I16,"","",TRUE)) - NOT(LEN(I16)))"),0.0) -> 0 | Z16: =IFERROR(__xludf.DUMMYFUNCTION("(COUNTA(SPLIT(J16,"","",TRUE)) - NOT(LEN(J16)))"),0.0) -> 0 | AA16: =IFERROR(__xludf.DUMMYFUNCTION("(COUNTA(SPLIT(K16,"","",TRUE)) - NOT(LEN(K16)))"),0.0) -> 0 | AB16: =IFERROR(__xludf.DUMMYFUNCTION("(COUNTA(SPLIT(L16,"","",TRUE)) - NOT(LEN(L16)))"),0.0) -> 0 | AC16: =IFERROR(__xludf.DUMMYFUNCTION("(COUNTA(SPLIT(M16,"","",TRUE)) - NOT(LEN(M16)))"),0.0) -> 0 | AD16: =IFERROR(__xludf.DUMMYFUNCTION("(COUNTA(SPLIT(N16,"","",TRUE)) - NOT(LEN(N16)))"),0.0) -> 0 | AE16: =IFERROR(__xludf.DUMMYFUNCTION("(COUNTA(SPLIT(O16,"","",TRUE)) - NOT(LEN(O16)))"),0.0) -> 0 | AF16: =IFERROR(__xludf.DUMMYFUNCTION("(COUNTA(SPLIT(P16,"","",TRUE)) - NOT(LEN(P16)))"),0.0) -> 0 | AG16: =IFERROR(__xludf.DUMMYFUNCTION("(COUNTA(SPLIT(Q16,"","",TRUE)) - NOT(LEN(Q16)))"),0.0) -> 0 | AH16: =SUM(R16:AG16) -> 0 | AI16: =R16*AI$4 -> 0 | AJ16: =S16*AJ$4 -> 0 | AK16: =T16*AK$4 -> 0 | AL16: =U16*AL$4 -> 0 | AM16: =V16*AM$4 -> 0 | AN16: =W16*AN$4 -> 0 | AO16: =X16*AO$4 -> 0 | AP16: =Y16*AP$4 -> 0 | ... AX16: =AG16*AX$4 -> 0 | AY16: =SUM(AI16:AX16) -> 0 | AZ16: =AY16/60 -> 0 | BA16: =AZ16/$AZ$1 -> 0 | BB16: =AZ16/2 -> 0 | BC16: =R16*BC$4 -> 0 | BD16: =S16*BD$4 -> 0 | BE16: =T16*BE$4 -> 0 | BF16: =U16*BF$4 -> 0 | BG16: =V16*BG$4 -> 0 | BH16: =W16*BH$4 -> 0 | BI16: =X16*BI$4 -> 0 | BJ16: =Y16*BJ$4 -> 0 | ... BR16: =AG16*BR$4 -> 0 | BS16: =sum(BC16:BR16) -> 0
D17: =$B17 | E17: =$B17 | F17: =$B17 | G17: =$B17 | H17: =$B17 | I17: =$B17 | K17: =B17 | L17: =C17 | M17: =C17 | N17: =C17 | R17: =IFERROR(__xludf.DUMMYFUNCTION("(COUNTA(SPLIT(B17,"","",TRUE)) - NOT(LEN(B17)))"),0.0) -> 0 | S17: =IFERROR(__xludf.DUMMYFUNCTION("(COUNTA(SPLIT(C17,"","",TRUE)) - NOT(LEN(C17)))"),0.0) -> 0 | T17: =IFERROR(__xludf.DUMMYFUNCTION("(COUNTA(SPLIT(D17,"","",TRUE)) - NOT(LEN(D17)))"),0.0) -> 0 | U17: =IFERROR(__xludf.DUMMYFUNCTION("(COUNTA(SPLIT(E17,"","",TRUE)) - NOT(LEN(E17)))"),0.0) -> 0 | V17: =IFERROR(__xludf.DUMMYFUNCTION("(COUNTA(SPLIT(F17,"","",TRUE)) - NOT(LEN(F17)))"),0.0) -> 0 | W17: =IFERROR(__xludf.DUMMYFUNCTION("(COUNTA(SPLIT(G17,"","",TRUE)) - NOT(LEN(G17)))"),0.0) -> 0 | X17: =IFERROR(__xludf.DUMMYFUNCTION("(COUNTA(SPLIT(H17,"","",TRUE)) - NOT(LEN(H17)))"),0.0) -> 0 | Y17: =IFERROR(__xludf.DUMMYFUNCTION("(COUNTA(SPLIT(I17,"","",TRUE)) - NOT(LEN(I17)))"),0.0) -> 0 | Z17: =IFERROR(__xludf.DUMMYFUNCTION("(COUNTA(SPLIT(J17,"","",TRUE)) - NOT(LEN(J17)))"),0.0) -> 0 | AA17: =IFERROR(__xludf.DUMMYFUNCTION("(COUNTA(SPLIT(K17,"","",TRUE)) - NOT(LEN(K17)))"),0.0) -> 0 | AB17: =IFERROR(__xludf.DUMMYFUNCTION("(COUNTA(SPLIT(L17,"","",TRUE)) - NOT(LEN(L17)))"),0.0) -> 0 | AC17: =IFERROR(__xludf.DUMMYFUNCTION("(COUNTA(SPLIT(M17,"","",TRUE)) - NOT(LEN(M17)))"),0.0) -> 0 | AD17: =IFERROR(__xludf.DUMMYFUNCTION("(COUNTA(SPLIT(N17,"","",TRUE)) - NOT(LEN(N17)))"),0.0) -> 0 | AE17: =IFERROR(__xludf.DUMMYFUNCTION("(COUNTA(SPLIT(O17,"","",TRUE)) - NOT(LEN(O17)))"),0.0) -> 0 | AF17: =IFERROR(__xludf.DUMMYFUNCTION("(COUNTA(SPLIT(P17,"","",TRUE)) - NOT(LEN(P17)))"),0.0) -> 0 | AG17: =IFERROR(__xludf.DUMMYFUNCTION("(COUNTA(SPLIT(Q17,"","",TRUE)) - NOT(LEN(Q17)))"),0.0) -> 0 | AH17: =SUM(R17:AG17) -> 0 | AI17: =R17*AI$4 -> 0 | AJ17: =S17*AJ$4 -> 0 | AK17: =T17*AK$4 -> 0 | AL17: =U17*AL$4 -> 0 | AM17: =V17*AM$4 -> 0 | AN17: =W17*AN$4 -> 0 | AO17: =X17*AO$4 -> 0 | AP17: =Y17*AP$4 -> 0 | ... AX17: =AG17*AX$4 -> 0 | AY17: =SUM(AI17:AX17) -> 0 | AZ17: =AY17/60 -> 0 | BA17: =AZ17/$AZ$1 -> 0 | BB17: =AZ17/2 -> 0 | BC17: =R17*BC$4 -> 0 | BD17: =S17*BD$4 -> 0 | BE17: =T17*BE$4 -> 0 | BF17: =U17*BF$4 -> 0 | BG17: =V17*BG$4 -> 0 | BH17: =W17*BH$4 -> 0 | BI17: =X17*BI$4 -> 0 | BJ17: =Y17*BJ$4 -> 0 | ... BR17: =AG17*BR$4 -> 0 | BS17: =sum(BC17:BR17) -> 0
D18: =$B18 | E18: =$B18 | F18: =$B18 | G18: =$B18 | H18: =$B18 | I18: =$B18 | K18: =B18 | L18: =C18 | M18: =C18 | N18: =C18 | R18: =IFERROR(__xludf.DUMMYFUNCTION("(COUNTA(SPLIT(B18,"","",TRUE)) - NOT(LEN(B18)))"),0.0) -> 0 | S18: =IFERROR(__xludf.DUMMYFUNCTION("(COUNTA(SPLIT(C18,"","",TRUE)) - NOT(LEN(C18)))"),0.0) -> 0 | T18: =IFERROR(__xludf.DUMMYFUNCTION("(COUNTA(SPLIT(D18,"","",TRUE)) - NOT(LEN(D18)))"),0.0) -> 0 | U18: =IFERROR(__xludf.DUMMYFUNCTION("(COUNTA(SPLIT(E18,"","",TRUE)) - NOT(LEN(E18)))"),0.0) -> 0 | V18: =IFERROR(__xludf.DUMMYFUNCTION("(COUNTA(SPLIT(F18,"","",TRUE)) - NOT(LEN(F18)))"),0.0) -> 0 | W18: =IFERROR(__xludf.DUMMYFUNCTION("(COUNTA(SPLIT(G18,"","",TRUE)) - NOT(LEN(G18)))"),0.0) -> 0 | X18: =IFERROR(__xludf.DUMMYFUNCTION("(COUNTA(SPLIT(H18,"","",TRUE)) - NOT(LEN(H18)))"),0.0) -> 0 | Y18: =IFERROR(__xludf.DUMMYFUNCTION("(COUNTA(SPLIT(I18,"","",TRUE)) - NOT(LEN(I18)))"),0.0) -> 0 | Z18: =IFERROR(__xludf.DUMMYFUNCTION("(COUNTA(SPLIT(J18,"","",TRUE)) - NOT(LEN(J18)))"),0.0) -> 0 | AA18: =IFERROR(__xludf.DUMMYFUNCTION("(COUNTA(SPLIT(K18,"","",TRUE)) - NOT(LEN(K18)))"),0.0) -> 0 | AB18: =IFERROR(__xludf.DUMMYFUNCTION("(COUNTA(SPLIT(L18,"","",TRUE)) - NOT(LEN(L18)))"),0.0) -> 0 | AC18: =IFERROR(__xludf.DUMMYFUNCTION("(COUNTA(SPLIT(M18,"","",TRUE)) - NOT(LEN(M18)))"),0.0) -> 0 | AD18: =IFERROR(__xludf.DUMMYFUNCTION("(COUNTA(SPLIT(N18,"","",TRUE)) - NOT(LEN(N18)))"),0.0) -> 0 | AE18: =IFERROR(__xludf.DUMMYFUNCTION("(COUNTA(SPLIT(O18,"","",TRUE)) - NOT(LEN(O18)))"),0.0) -> 0 | AF18: =IFERROR(__xludf.DUMMYFUNCTION("(COUNTA(SPLIT(P18,"","",TRUE)) - NOT(LEN(P18)))"),0.0) -> 0 | AG18: =IFERROR(__xludf.DUMMYFUNCTION("(COUNTA(SPLIT(Q18,"","",TRUE)) - NOT(LEN(Q18)))"),0.0) -> 0 | AH18: =SUM(R18:AG18) -> 0 | AI18: =R18*AI$4 -> 0 | AJ18: =S18*AJ$4 -> 0 | AK18: =T18*AK$4 -> 0 | AL18: =U18*AL$4 -> 0 | AM18: =V18*AM$4 -> 0 | AN18: =W18*AN$4 -> 0 | AO18: =X18*AO$4 -> 0 | AP18: =Y18*AP$4 -> 0 | ... AX18: =AG18*AX$4 -> 0 | AY18: =SUM(AI18:AX18) -> 0 | AZ18: =AY18/60 -> 0 | BA18: =AZ18/$AZ$1 -> 0 | BB18: =AZ18/2 -> 0 | BC18: =R18*BC$4 -> 0 | BD18: =S18*BD$4 -> 0 | BE18: =T18*BE$4 -> 0 | BF18: =U18*BF$4 -> 0 | BG18: =V18*BG$4 -> 0 | BH18: =W18*BH$4 -> 0 | BI18: =X18*BI$4 -> 0 | BJ18: =Y18*BJ$4 -> 0 | ... BR18: =AG18*BR$4 -> 0 | BS18: =sum(BC18:BR18) -> 0
D19: =$B19 | E19: =$B19 | F19: =$B19 | G19: =$B19 | H19: =$B19 | I19: =$B19 | K19: =B19 | L19: =C19 | M19: =C19 | N19: =C19 | R19: =IFERROR(__xludf.DUMMYFUNCTION("(COUNTA(SPLIT(B19,"","",TRUE)) - NOT(LEN(B19)))"),0.0) -> 0 | S19: =IFERROR(__xludf.DUMMYFUNCTION("(COUNTA(SPLIT(C19,"","",TRUE)) - NOT(LEN(C19)))"),0.0) -> 0 | T19: =IFERROR(__xludf.DUMMYFUNCTION("(COUNTA(SPLIT(D19,"","",TRUE)) - NOT(LEN(D19)))"),0.0) -> 0 | U19: =IFERROR(__xludf.DUMMYFUNCTION("(COUNTA(SPLIT(E19,"","",TRUE)) - NOT(LEN(E19)))"),0.0) -> 0 | V19: =IFERROR(__xludf.DUMMYFUNCTION("(COUNTA(SPLIT(F19,"","",TRUE)) - NOT(LEN(F19)))"),0.0) -> 0 | W19: =IFERROR(__xludf.DUMMYFUNCTION("(COUNTA(SPLIT(G19,"","",TRUE)) - NOT(LEN(G19)))"),0.0) -> 0 | X19: =IFERROR(__xludf.DUMMYFUNCTION("(COUNTA(SPLIT(H19,"","",TRUE)) - NOT(LEN(H19)))"),0.0) -> 0 | Y19: =IFERROR(__xludf.DUMMYFUNCTION("(COUNTA(SPLIT(I19,"","",TRUE)) - NOT(LEN(I19)))"),0.0) -> 0 | Z19: =IFERROR(__xludf.DUMMYFUNCTION("(COUNTA(SPLIT(J19,"","",TRUE)) - NOT(LEN(J19)))"),0.0) -> 0 | AA19: =IFERROR(__xludf.DUMMYFUNCTION("(COUNTA(SPLIT(K19,"","",TRUE)) - NOT(LEN(K19)))"),0.0) -> 0 | AB19: =IFERROR(__xludf.DUMMYFUNCTION("(COUNTA(SPLIT(L19,"","",TRUE)) - NOT(LEN(L19)))"),0.0) -> 0 | AC19: =IFERROR(__xludf.DUMMYFUNCTION("(COUNTA(SPLIT(M19,"","",TRUE)) - NOT(LEN(M19)))"),0.0) -> 0 | AD19: =IFERROR(__xludf.DUMMYFUNCTION("(COUNTA(SPLIT(N19,"","",TRUE)) - NOT(LEN(N19)))"),0.0) -> 0 | AE19: =IFERROR(__xludf.DUMMYFUNCTION("(COUNTA(SPLIT(O19,"","",TRUE)) - NOT(LEN(O19)))"),0.0) -> 0 | AF19: =IFERROR(__xludf.DUMMYFUNCTION("(COUNTA(SPLIT(P19,"","",TRUE)) - NOT(LEN(P19)))"),0.0) -> 0 | AG19: =IFERROR(__xludf.DUMMYFUNCTION("(COUNTA(SPLIT(Q19,"","",TRUE)) - NOT(LEN(Q19)))"),0.0) -> 0 | AH19: =SUM(R19:AG19) -> 0 | AI19: =R19*AI$4 -> 0 | AJ19: =S19*AJ$4 -> 0 | AK19: =T19*AK$4 -> 0 | AL19: =U19*AL$4 -> 0 | AM19: =V19*AM$4 -> 0 | AN19: =W19*AN$4 -> 0 | AO19: =X19*AO$4 -> 0 | AP19: =Y19*AP$4 -> 0 | ... AX19: =AG19*AX$4 -> 0 | AY19: =SUM(AI19:AX19) -> 0 | AZ19: =AY19/60 -> 0 | BA19: =AZ19/$AZ$1 -> 0 | BB19: =AZ19/2 -> 0 | BC19: =R19*BC$4 -> 0 | BD19: =S19*BD$4 -> 0 | BE19: =T19*BE$4 -> 0 | BF19: =U19*BF$4 -> 0 | BG19: =V19*BG$4 -> 0 | BH19: =W19*BH$4 -> 0 | BI19: =X19*BI$4 -> 0 | BJ19: =Y19*BJ$4 -> 0 | ... BR19: =AG19*BR$4 -> 0 | BS19: =sum(BC19:BR19) -> 0
D20: =$B20 | E20: =$B20 | F20: =$B20 | G20: =$B20 | H20: =$B20 | I20: =$B20 | K20: =B20 | L20: =C20 | M20: =C20 | N20: =C20 | R20: =IFERROR(__xludf.DUMMYFUNCTION("(COUNTA(SPLIT(B20,"","",TRUE)) - NOT(LEN(B20)))"),0.0) -> 0 | S20: =IFERROR(__xludf.DUMMYFUNCTION("(COUNTA(SPLIT(C20,"","",TRUE)) - NOT(LEN(C20)))"),0.0) -> 0 | T20: =IFERROR(__xludf.DUMMYFUNCTION("(COUNTA(SPLIT(D20,"","",TRUE)) - NOT(LEN(D20)))"),0.0) -> 0 | U20: =IFERROR(__xludf.DUMMYFUNCTION("(COUNTA(SPLIT(E20,"","",TRUE)) - NOT(LEN(E20)))"),0.0) -> 0 | V20: =IFERROR(__xludf.DUMMYFUNCTION("(COUNTA(SPLIT(F20,"","",TRUE)) - NOT(LEN(F20)))"),0.0) -> 0 | W20: =IFERROR(__xludf.DUMMYFUNCTION("(COUNTA(SPLIT(G20,"","",TRUE)) - NOT(LEN(G20)))"),0.0) -> 0 | X20: =IFERROR(__xludf.DUMMYFUNCTION("(COUNTA(SPLIT(H20,"","",TRUE)) - NOT(LEN(H20)))"),0.0) -> 0 | Y20: =IFERROR(__xludf.DUMMYFUNCTION("(COUNTA(SPLIT(I20,"","",TRUE)) - NOT(LEN(I20)))"),0.0) -> 0 | Z20: =IFERROR(__xludf.DUMMYFUNCTION("(COUNTA(SPLIT(J20,"","",TRUE)) - NOT(LEN(J20)))"),0.0) -> 0 | AA20: =IFERROR(__xludf.DUMMYFUNCTION("(COUNTA(SPLIT(K20,"","",TRUE)) - NOT(LEN(K20)))"),0.0) -> 0 | AB20: =IFERROR(__xludf.DUMMYFUNCTION("(COUNTA(SPLIT(L20,"","",TRUE)) - NOT(LEN(L20)))"),0.0) -> 0 | AC20: =IFERROR(__xludf.DUMMYFUNCTION("(COUNTA(SPLIT(M20,"","",TRUE)) - NOT(LEN(M20)))"),0.0) -> 0 | AD20: =IFERROR(__xludf.DUMMYFUNCTION("(COUNTA(SPLIT(N20,"","",TRUE)) - NOT(LEN(N20)))"),0.0) -> 0 | AE20: =IFERROR(__xludf.DUMMYFUNCTION("(COUNTA(SPLIT(O20,"","",TRUE)) - NOT(LEN(O20)))"),0.0) -> 0 | AF20: =IFERROR(__xludf.DUMMYFUNCTION("(COUNTA(SPLIT(P20,"","",TRUE)) - NOT(LEN(P20)))"),0.0) -> 0 | AG20: =IFERROR(__xludf.DUMMYFUNCTION("(COUNTA(SPLIT(Q20,"","",TRUE)) - NOT(LEN(Q20)))"),0.0) -> 0 | AH20: =SUM(R20:AG20) -> 0 | AI20: =R20*AI$4 -> 0 | AJ20: =S20*AJ$4 -> 0 | AK20: =T20*AK$4 -> 0 | AL20: =U20*AL$4 -> 0 | AM20: =V20*AM$4 -> 0 | AN20: =W20*AN$4 -> 0 | AO20: =X20*AO$4 -> 0 | AP20: =Y20*AP$4 -> 0 | ... AX20: =AG20*AX$4 -> 0 | AY20: =SUM(AI20:AX20) -> 0 | AZ20: =AY20/60 -> 0 | BA20: =AZ20/$AZ$1 -> 0 | BB20: =AZ20/2 -> 0 | BC20: =R20*BC$4 -> 0 | BD20: =S20*BD$4 -> 0 | BE20: =T20*BE$4 -> 0 | BF20: =U20*BF$4 -> 0 | BG20: =V20*BG$4 -> 0 | BH20: =W20*BH$4 -> 0 | BI20: =X20*BI$4 -> 0 | BJ20: =Y20*BJ$4 -> 0 | ... BR20: =AG20*BR$4 -> 0 | BS20: =sum(BC20:BR20) -> 0
D21: =$B21 | E21: =$B21 | F21: =$B21 | G21: =$B21 | H21: =$B21 | I21: =$B21 | K21: =B21 | L21: =C21 | M21: =C21 | N21: =C21 | R21: =IFERROR(__xludf.DUMMYFUNCTION("(COUNTA(SPLIT(B21,"","",TRUE)) - NOT(LEN(B21)))"),0.0) -> 0 | S21: =IFERROR(__xludf.DUMMYFUNCTION("(COUNTA(SPLIT(C21,"","",TRUE)) - NOT(LEN(C21)))"),0.0) -> 0 | T21: =IFERROR(__xludf.DUMMYFUNCTION("(COUNTA(SPLIT(D21,"","",TRUE)) - NOT(LEN(D21)))"),0.0) -> 0 | U21: =IFERROR(__xludf.DUMMYFUNCTION("(COUNTA(SPLIT(E21,"","",TRUE)) - NOT(LEN(E21)))"),0.0) -> 0 | V21: =IFERROR(__xludf.DUMMYFUNCTION("(COUNTA(SPLIT(F21,"","",TRUE)) - NOT(LEN(F21)))"),0.0) -> 0 | W21: =IFERROR(__xludf.DUMMYFUNCTION("(COUNTA(SPLIT(G21,"","",TRUE)) - NOT(LEN(G21)))"),0.0) -> 0 | X21: =IFERROR(__xludf.DUMMYFUNCTION("(COUNTA(SPLIT(H21,"","",TRUE)) - NOT(LEN(H21)))"),0.0) -> 0 | Y21: =IFERROR(__xludf.DUMMYFUNCTION("(COUNTA(SPLIT(I21,"","",TRUE)) - NOT(LEN(I21)))"),0.0) -> 0 | Z21: =IFERROR(__xludf.DUMMYFUNCTION("(COUNTA(SPLIT(J21,"","",TRUE)) - NOT(LEN(J21)))"),0.0) -> 0 | AA21: =IFERROR(__xludf.DUMMYFUNCTION("(COUNTA(SPLIT(K21,"","",TRUE)) - NOT(LEN(K21)))"),0.0) -> 0 | AB21: =IFERROR(__xludf.DUMMYFUNCTION("(COUNTA(SPLIT(L21,"","",TRUE)) - NOT(LEN(L21)))"),0.0) -> 0 | AC21: =IFERROR(__xludf.DUMMYFUNCTION("(COUNTA(SPLIT(M21,"","",TRUE)) - NOT(LEN(M21)))"),0.0) -> 0 | AD21: =IFERROR(__xludf.DUMMYFUNCTION("(COUNTA(SPLIT(N21,"","",TRUE)) - NOT(LEN(N21)))"),0.0) -> 0 | AE21: =IFERROR(__xludf.DUMMYFUNCTION("(COUNTA(SPLIT(O21,"","",TRUE)) - NOT(LEN(O21)))"),0.0) -> 0 | AF21: =IFERROR(__xludf.DUMMYFUNCTION("(COUNTA(SPLIT(P21,"","",TRUE)) - NOT(LEN(P21)))"),0.0) -> 0 | AG21: =IFERROR(__xludf.DUMMYFUNCTION("(COUNTA(SPLIT(Q21,"","",TRUE)) - NOT(LEN(Q21)))"),0.0) -> 0 | AH21: =SUM(R21:AG21) -> 0 | AI21: =R21*AI$4 -> 0 | AJ21: =S21*AJ$4 -> 0 | AK21: =T21*AK$4 -> 0 | AL21: =U21*AL$4 -> 0 | AM21: =V21*AM$4 -> 0 | AN21: =W21*AN$4 -> 0 | AO21: =X21*AO$4 -> 0 | AP21: =Y21*AP$4 -> 0 | ... AX21: =AG21*AX$4 -> 0 | AY21: =SUM(AI21:AX21) -> 0 | AZ21: =AY21/60 -> 0 | BA21: =AZ21/$AZ$1 -> 0 | BB21: =AZ21/2 -> 0 | BC21: =R21*BC$4 -> 0 | BD21: =S21*BD$4 -> 0 | BE21: =T21*BE$4 -> 0 | BF21: =U21*BF$4 -> 0 | BG21: =V21*BG$4 -> 0 | BH21: =W21*BH$4 -> 0 | BI21: =X21*BI$4 -> 0 | BJ21: =Y21*BJ$4 -> 0 | ... BR21: =AG21*BR$4 -> 0 | BS21: =sum(BC21:BR21) -> 0
D22: =$B22 | E22: =$B22 | F22: =$B22 | G22: =$B22 | H22: =$B22 | I22: =$B22 | K22: =B22 | L22: =C22 | M22: =C22 | N22: =C22 | R22: =IFERROR(__xludf.DUMMYFUNCTION("(COUNTA(SPLIT(B22,"","",TRUE)) - NOT(LEN(B22)))"),0.0) -> 0 | S22: =IFERROR(__xludf.DUMMYFUNCTION("(COUNTA(SPLIT(C22,"","",TRUE)) - NOT(LEN(C22)))"),0.0) -> 0 | T22: =IFERROR(__xludf.DUMMYFUNCTION("(COUNTA(SPLIT(D22,"","",TRUE)) - NOT(LEN(D22)))"),0.0) -> 0 | U22: =IFERROR(__xludf.DUMMYFUNCTION("(COUNTA(SPLIT(E22,"","",TRUE)) - NOT(LEN(E22)))"),0.0) -> 0 | V22: =IFERROR(__xludf.DUMMYFUNCTION("(COUNTA(SPLIT(F22,"","",TRUE)) - NOT(LEN(F22)))"),0.0) -> 0 | W22: =IFERROR(__xludf.DUMMYFUNCTION("(COUNTA(SPLIT(G22,"","",TRUE)) - NOT(LEN(G22)))"),0.0) -> 0 | X22: =IFERROR(__xludf.DUMMYFUNCTION("(COUNTA(SPLIT(H22,"","",TRUE)) - NOT(LEN(H22)))"),0.0) -> 0 | Y22: =IFERROR(__xludf.DUMMYFUNCTION("(COUNTA(SPLIT(I22,"","",TRUE)) - NOT(LEN(I22)))"),0.0) -> 0 | Z22: =IFERROR(__xludf.DUMMYFUNCTION("(COUNTA(SPLIT(J22,"","",TRUE)) - NOT(LEN(J22)))"),0.0) -> 0 | AA22: =IFERROR(__xludf.DUMMYFUNCTION("(COUNTA(SPLIT(K22,"","",TRUE)) - NOT(LEN(K22)))"),0.0) -> 0 | AB22: =IFERROR(__xludf.DUMMYFUNCTION("(COUNTA(SPLIT(L22,"","",TRUE)) - NOT(LEN(L22)))"),0.0) -> 0 | AC22: =IFERROR(__xludf.DUMMYFUNCTION("(COUNTA(SPLIT(M22,"","",TRUE)) - NOT(LEN(M22)))"),0.0) -> 0 | AD22: =IFERROR(__xludf.DUMMYFUNCTION("(COUNTA(SPLIT(N22,"","",TRUE)) - NOT(LEN(N22)))"),0.0) -> 0 | AE22: =IFERROR(__xludf.DUMMYFUNCTION("(COUNTA(SPLIT(O22,"","",TRUE)) - NOT(LEN(O22)))"),0.0) -> 0 | AF22: =IFERROR(__xludf.DUMMYFUNCTION("(COUNTA(SPLIT(P22,"","",TRUE)) - NOT(LEN(P22)))"),0.0) -> 0 | AG22: =IFERROR(__xludf.DUMMYFUNCTION("(COUNTA(SPLIT(Q22,"","",TRUE)) - NOT(LEN(Q22)))"),0.0) -> 0 | AH22: =SUM(R22:AG22) -> 0 | AI22: =R22*AI$4 -> 0 | AJ22: =S22*AJ$4 -> 0 | AK22: =T22*AK$4 -> 0 | AL22: =U22*AL$4 -> 0 | AM22: =V22*AM$4 -> 0 | AN22: =W22*AN$4 -> 0 | AO22: =X22*AO$4 -> 0 | AP22: =Y22*AP$4 -> 0 | ... AX22: =AG22*AX$4 -> 0 | AY22: =SUM(AI22:AX22) -> 0 | AZ22: =AY22/60 -> 0 | BA22: =AZ22/$AZ$1 -> 0 | BB22: =AZ22/2 -> 0 | BC22: =R22*BC$4 -> 0 | BD22: =S22*BD$4 -> 0 | BE22: =T22*BE$4 -> 0 | BF22: =U22*BF$4 -> 0 | BG22: =V22*BG$4 -> 0 | BH22: =W22*BH$4 -> 0 | BI22: =X22*BI$4 -> 0 | BJ22: =Y22*BJ$4 -> 0 | ... BR22: =AG22*BR$4 -> 0 | BS22: =sum(BC22:BR22) -> 0
AG23: Totale | AH23: =SUM(AH6:AH22) -> 11 | AX23: Totale | AY23: =SUM(AY6:AY22) -> 240 | AZ23: =SUM(AZ6:AZ22) -> 4 | BA23: =SUM(BA6:BA22) -> 0.5 | BB23: =SUM(BB6:BB22) -> 2 | BR23: Totale | BS23: =sum(BS6:BS22) -> 199.2

Sheet DevUnits
B1: Dev Units
E2: entity_operations | L2: fields_operations | O2: relations
A3: Source generation | B3: enity | C3: field | D3: index | E3: create | F3: store | G3: show | H3: edit | I3: update | J3: destory | K3: soft-delete | L3: filter | M3: sorting | N3: validation | O3: oto | P3: otm | Q3: mtm
A4: table | B4: x | Q4: x
A5: column | B5: x | C5: x | K5: x | O5: x | P5: x
A6: model | B6: x
A7: model relations | O7: x | P7: x | Q7: x
A8: controller | B8: x
A9: controller action | D9: x | E9: x | F9: x | G9: x | I9: x | J9: x | K9: x
A10: routes | D10: x | E10: x | F10: x | G10: x | I10: x | J10: x | K10: x
A11: cta | D11: x | E11: x | F11: x | G11: x | I11: x | J11: x | K11: x | L11: x | M11: x
A12: success message | E12: x | F12: x | G12: x | I12: x | J12: x | K12: x
A13: errore message | E13: x | F13: x | G13: x | I13: x | J13: x | K13: x | N13: x
A14: view | D14: x | E14: x | G14: x | H14: x
A15: form | C15: x | L15: x | Q15: x
A16: log trace | F16: x | I16: x | J16: x | K16: x
A17: navigation | B17: x | D17: x | E17: x | F17: x | G17: x | I17: x | J17: x | K17: x
A18: fe logic | N18: x | Q18: x
A19: be logic | N19: x | Q19: x
A20: Peso H | B20: =COUNTA(B4:B19) -> 5 | C20: =COUNTA(C4:C19) -> 2 | D20: =COUNTA(D4:D19) -> 5 | E20: =COUNTA(E4:E19) -> 7 | F20: =COUNTA(F4:F19) -> 7 | G20: =COUNTA(G4:G19) -> 7 | H20: =COUNTA(H4:H19) -> 1 | I20: =COUNTA(I4:I19) -> 7 | ... Q20: =COUNTA(Q4:Q19) -> 5
